Workbook

Sheet Export Summary
B3: This document was exported from Numbers. Each table was converted to an Excel worksheet. All other objects on each Numbers sheet were placed on separate worksheets. Please be aware that formula calculations may differ in Excel.
B7: Numbers Sheet Name | C7: Numbers Table Name | D7: Excel Worksheet Name
B9: PROJECT OVERVIEW
C10: Table 1 | D10: PROJECT OVERVIEW
B11: TEST PLAN
C12: Table 1 | D12: TEST PLAN
B13: FIELD LOG
C14: Table 1 | D14: FIELD LOG
B15: RUN DETAIL
C16: Table 1 | D16: RUN DETAIL
B17: SUMMARY
C18: Table 1 | D18: SUMMARY
B19: TEST ITERATIONS
C20: Table 1 | D20: TEST ITERATIONS

Sheet PROJECT OVERVIEW
B2: FIELD QUALITY ASSURANCE
B3: FQA-001 — Mobile Media Service Continuity During a Repeatable Real-World Route
B4: Independent consumer-device field study · Methodology adapted from public GSMA TS.11 field-test principles
B6: TEST ID | C6: VERSION | D6: STATUS | E6: DEVICE UNDER TEST
B7: FQA-001 | C7: 1.0 | D7: Baseline Testing | E7: iPhone
B9: RESEARCH QUESTION | C9: Does an active internet-based media session remain usable while an iPhone moves through a repeatable real-world route containing changing connectivity conditions?
B11: OBJECTIVE | C11: To practise disciplined field quality assurance on a consumer device: define an expected behaviour, execute a fixed and repeatable procedure, observe real-world outcomes without instrumentation, and record findings in a form that supports reproducibility, isolation, and cautious conclusions. The objective is methodological rigour, not a verdict on any product.
B13: SERVICE UNDER TEST | C13: YouTube Premium background audio played through Powerbeats Pro, with the YouTube application minimised so that playback continues in the background for the duration of the route.
B15: EXPECTED BEHAVIOUR | C15: Playback should remain usable throughout the route without an unexpected interruption requiring user intervention.
B17: METHODOLOGY | C17: Expected behaviour → controlled procedure → real-world observation → reproducibility → isolation → evidence → cautious conclusion. A single baseline configuration is held constant across a campaign of repeated runs over one fixed route. Configuration, route, service, and procedure are documented before testing begins. Each run is logged immediately afterwards. Later campaigns change one variable at a time, and only where a real observation justifies the change.
B19: SCOPE | C19: One iPhone. One fixed out-and-back walking route with five defined landmarks (A-E), following A → B → C → D → E outbound and E → D → C → B → A on return. One active service. One audio accessory. Baseline campaign of five runs, with the field log sized for further runs. Out of scope for FQA-001: Apple Watch, Mac, comparative or reference devices, deliberate degradation of connectivity, and any change to device settings mid-run.
B21: LIMITATIONS | C21: No protocol logs, Cell IDs, signal-strength captures, engineering builds, internal diagnostic tools, or controlled network conditions are available. Radio conditions, network load, and environmental factors are uncontrolled and unmeasured. Observations are perceptual and human-timed; durations are approximate. Route position is recorded by landmark, not by precise location. No product requirement document exists against which a result could be called a failure, which is why the result categories use OBSERVED INTERRUPTION rather than FAIL.
B24: OBSERVATION ≠ INTERPRETATION
B25: Observation | C25: What was directly perceived during the run, stated plainly and without cause. Example form: "Audio stopped for roughly four seconds shortly after leaving the building, then resumed on its own."
B26: Interpretation | C26: A candidate explanation, explicitly labelled as such and held loosely. Example form: "This may be consistent with a transition away from Wi-Fi, but no network evidence was collected and other explanations are not excluded."
B27: Rule for this project | C27: No observation in the field log may name a Wi-Fi-to-cellular transition, a 5G→LTE handover, a cell reselection, or any other network event. Such statements belong only in the interpretation column, and only with the uncertainty stated alongside them.
B29: This project adapts concepts from GSMA TS.11 for independent consumer-device field testing. It is not a GSMA certification test and does not use proprietary network, protocol, or device diagnostic tooling.
B31: Not affiliated with, endorsed by, or representative of any employer, carrier, device manufacturer, or standards body. All data is collected on personally owned equipment under ordinary consumer conditions.
B33: CELL LEGEND
C34: Input — you complete this cell
C35: Calculated — formula driven, do not overwrite
C36: Reference — fixed project text

Sheet TEST PLAN
B2: Test Plan
B3: FQA-001 · Baseline configuration, route definition, procedure, and result definitions · Version 1.0
B6: BASELINE CONFIGURATION · record once per campaign, or again whenever it changes
B8: iPhone model | C8: iPhone 15 Pro
B9: iOS version | C9: 27
B10: Carrier | C10: T-Mobile
B11: Wi-Fi | C11: On
B12: Cellular Data | C12: On
B13: Low Power Mode | C13: Off
B14: VPN | C14: Off
B15: Starting battery %
B16: Audio device | C16: Powerbeats Pro
B17: Media service | C17: YouTube Premium
B18: Playback type | C18: Background audio
B19: Predetermined media (title / URL) | C19: YouTube videos lasting for at least 35 minutes.
B20: Starting volume | C20: 80
B21: Other relevant settings
C22: Starting battery % is recorded per run in the FIELD LOG; the value above is the campaign default.
B24: ROUTE DEFINITION · five fixed landmarks, following the same out-and-back route every run
B26: Landmark | C26: Name | D26: Description — fixed physical reference point
B27: A | C27: Starting point — inside apartment | D27: Stationary indoor start position. Playback is confirmed normal here before the walk begins.
B28: B | C28: Building exit | D28: Street level exit from apartment property onto the public sidewalk; beginning of the outdoor walking portion of the route.
B29: C | C29: First outdoor landmark | D29: Pease Park entrance at Kingsbury Street, identified by the stone archway and park entrance signage.
B30: D | C30: Mid-route landmark | D30: Unpaved trail segment within Pease Park/Shoal Creek Trail, after entering the wooded portion of the route.
B31: E | C31: Turnaround point | D31: Shoal Creek Trail Mile 2.0 marker; fixed turnaround point before retracing the route.
B33: TEST PROCEDURE · executed identically on every run
B35: 1 | C35: Record run number, date and time, starting battery percentage, and any unusual environmental conditions.
B36: 2 | C36: Connect Powerbeats Pro normally.
B37: 3 | C37: Confirm Wi-Fi and Cellular Data are enabled.
B38: 4 | C38: Open the predetermined YouTube video / media.
B39: 5 | C39: Begin playback while stationary at Point A.
B40: 6 | C40: Confirm normal playback.
B41: 7 | C41: Minimise YouTube while maintaining background playback.
B42: 8 | C42: Walk the defined out-and-back route at a normal pace, following A→ B→ C→ D→ E, then retracing E→ D→ C→ B → A.
B43: 9 | C43: Do not manually change connectivity settings during the run.
B44: 10 | C44: Do not restart or reload playback unless intervention becomes necessary.
B45: 11 | C45: Note any observable interruption and approximately where it occurred.
B46: 12 | C46: Continue to Point E, then retrace the same route to Point A while maintaining background playback.
... B48: 14 | C48: Complete the field log immediately after the run.
B50: RESULT DEFINITIONS · exactly three categories
...

Sheet FIELD LOG
A2: Field Log
A3: FQA-001 · One row per run · Complete immediately after each run · Baseline campaign = 5 runs
A5: Formats — Date: YYYY-MM-DD · Start time: HH:MM · Battery: whole number · Duration: whole seconds · Leave any cell blank where it does not apply. Record nothing you did not actually observe.
A6: RUN CONTEXT | F6: DIRECT OBSERVATION — what happened | M6: INTERPRETATION — what it might mean
A7: Run ID | B7: Date | C7: Start time | D7: Start battery % | E7: Environmental / route conditions | F7: Interruption observed? | G7: Approx. route location | H7: Approx. duration (s) | I7: Automatically recovered? | J7: User intervention required? | K7: Result | L7: Direct observation | M7: Interpretation / hypothesis | N7: Next isolation step
A8: FQA-001-R01 | B8: 46284 | C8: 46286.644 | D8: 63 | E8: Normal route; no unusual conditions observed. | F8: No | I8: N/A | J8: No | K8: PASS | L8: Continuous background audio playback was maintained throughout the complete out-and-back route. No perceptible interruption, buffering, or playback degradation was observed.
A9: FQA-001-R02 | B9: 46284 | C9: 46286.762 | D9: 90 | E9: Normal route; no unusual conditions observed. | F9: No | I9: N/A | J9: No | K9: PASS | L9: Continuous background audio playback was maintained throughout the complete out-and-back route. No perceptible interruption, buffering, or playback degradation was observed.
A10: FQA-001-R03 | B10: 46286 | C10: 46286.651 | D10: 36 | E10: Normal route; no unusual conditions observed. | F10: No | I10: N/A | J10: No | K10: PASS | L10: Continuous background audio playback was maintained throughout the complete out-and-back route. No perceptible interruption, buffering, or playback degradation was observed.
A11: FQA-001-R04
A12: FQA-001-R05
A13: FQA-001-R06
A14: FQA-001-R07
A15: FQA-001-R08
A16: FQA-001-R09
A17: FQA-001-R10
A18: FQA-001-R11
A19: FQA-001-R12
A20: FQA-001-R13
A21: FQA-001-R14
A22: FQA-001-R15
... A49: Direct observation (column L) states only what was perceived — sound, silence, timing, place. Interpretation (columns M–N) is shaded differently because it is not evidence: it is a candidate explanation to be tested by changing one variable at a time.

Sheet RUN DETAIL
B2: Run Detail
B3: FQA-001 · Deep-dive template for a single run of interest · Duplicate this sheet per investigated run
B6: Run ID
B8: EVIDENCE — what is on the record
B10: Preconditions
C11: Configuration at the start of the run: device state, settings, battery, audio device, media, volume. Note anything that differed from the baseline configuration.
B12: Route / location
C13: Which landmarks or segments the run covered, and where along the route the behaviour occurred.
B14: Timeline
C15: Sequence of the run with approximate clock or elapsed times: playback start, departure, landmark passes, the event, recovery, arrival.
B16: Exact observed behaviour
C17: What was perceived, stated without cause. Sound, silence, stutter, buffering, degradation — and nothing about why.
B18: Approximate duration
C19: Human-timed, stated as approximate.
B20: Automatic recovery
C21: Did playback resume without any user action? If so, roughly how long did that take?
B22: Intervention
C23: What, if anything, you had to do. If you intervened, note the point at which you stopped waiting.
B24: Reproducibility
C25: Has this been seen in other runs? In which ones, and at what point in the route? How many runs have been attempted under this configuration?
B27: BOUNDARIES — what can and cannot be claimed
B29: Potential variables
C30: Everything that plausibly differed and was not controlled: weather, time of day, route deviation, pedestrian density, battery level, thermal state, accessory battery, network load.
B31: Evidence available
C32: What genuinely supports the account: the field log entry, timing, repeated observation across runs, anything recorded at the time.
B33: Evidence unavailable
C34: What would be needed and is not available: protocol logs, Cell IDs, signal measurements, network-side data, device diagnostics, controlled conditions.
B36: INFERENCE — clearly labelled as such
B38: Hypothesis
C39: A candidate explanation, phrased as a possibility and not as a finding.
B40: Confidence / uncertainty
C41: How strongly this is held, what would weaken it, and which competing explanations remain open.
B43: NEXT MOVE
B45: Proposed next test
C46: The smallest test that would move this forward, described concretely enough to execute.
B47: Single variable to change
C48: Exactly one. Everything else is held constant.
B50: “What single variable would give me the most information next?”

Sheet SUMMARY
B2: Summary
B3: FQA-001 · Calculated from the FIELD LOG · Values update automatically as runs are recorded
B6: CAMPAIGN COUNTS
B8: Runs logged | C8: {=COUNTA('FIELD LOG'!$K$8:$K$47)} -> 3 | E8: Any row with a result recorded.
B9: Total valid runs | C9: {=COUNTIF('FIELD LOG'!$K$8:$K$47,"PASS")+COUNTIF('FIELD LOG'!$K$8:$K$47,"OBSERVED INTERRUPTION")} -> 3 | E9: Excludes invalid runs.
B10: Passes | C10: {=COUNTIF('FIELD LOG'!$K$8:$K$47,"PASS")} -> 3
B11: Observed interruptions | C11: {=COUNTIF('FIELD LOG'!$K$8:$K$47,"OBSERVED INTERRUPTION")} -> 0
B12: Invalid runs | C12: {=COUNTIF('FIELD LOG'!$K$8:$K$47,"INVALID RUN")} -> 0 | E12: Procedure compromised; excluded from rates.
B13: Baseline target | C13: 5 | E13: Runs planned for the FQA-001 baseline campaign.
B14: Baseline runs remaining | C14: {=MAX(0,$C$13-$C$9)} -> 2
B16: RATES
B18: Interruption rate | C18: {=_xlfn.IFERROR($C$11/$C$9,"")} -> 0 | E18: Observed interruptions ÷ valid runs.
B19: Automatic recovery count | C19: {=_xlfn.COUNTIFS('FIELD LOG'!$F$8:$F$47,"Yes",'FIELD LOG'!$I$8:$I$47,"Yes")} -> 0 | E19: Interruptions that resolved without user action.
B20: Automatic recovery rate | C20: {=_xlfn.IFERROR($C$19/$C$11,"")} | E20: Automatic recoveries ÷ observed interruptions.
B21: Interventions required | C21: {=_xlfn.COUNTIFS('FIELD LOG'!$F$8:$F$47,"Yes",'FIELD LOG'!$J$8:$J$47,"Yes")} -> 0 | E21: Runs where the device had to be touched to restore playback.
B23: OBSERVED INTERRUPTIONS BY ROUTE LOCATION
B25: Landmark / segment | C25: Count
B26: A (apartment) | C26: {=_xlfn.COUNTIFS('FIELD LOG'!$G$8:$G$47,$B$26,'FIELD LOG'!$F$8:$F$47,"Yes")} -> 0
B27: B (building exit) | C27: {=_xlfn.COUNTIFS('FIELD LOG'!$G$8:$G$47,$B$27,'FIELD LOG'!$F$8:$F$47,"Yes")} -> 0
B28: C (first outdoor) | C28: {=_xlfn.COUNTIFS('FIELD LOG'!$G$8:$G$47,$B$28,'FIELD LOG'!$F$8:$F$47,"Yes")} -> 0
B29: D (mid-route) | C29: {=_xlfn.COUNTIFS('FIELD LOG'!$G$8:$G$47,$B$29,'FIELD LOG'!$F$8:$F$47,"Yes")} -> 0
B30: E (destination) | C30: {=_xlfn.COUNTIFS('FIELD LOG'!$G$8:$G$47,$B$30,'FIELD LOG'!$F$8:$F$47,"Yes")} -> 0
B31: Between A and B | C31: {=_xlfn.COUNTIFS('FIELD LOG'!$G$8:$G$47,$B$31,'FIELD LOG'!$F$8:$F$47,"Yes")} -> 0
B32: Between B and C | C32: {=_xlfn.COUNTIFS('FIELD LOG'!$G$8:$G$47,$B$32,'FIELD LOG'!$F$8:$F$47,"Yes")} -> 0
B33: Between C and D | C33: {=_xlfn.COUNTIFS('FIELD LOG'!$G$8:$G$47,$B$33,'FIELD LOG'!$F$8:$F$47,"Yes")} -> 0
B34: Between D and E | C34: {=_xlfn.COUNTIFS('FIELD LOG'!$G$8:$G$47,$B$34,'FIELD LOG'!$F$8:$F$47,"Yes")} -> 0
B35: Unclear | C35: {=_xlfn.COUNTIFS('FIELD LOG'!$G$8:$G$47,$B$35,'FIELD LOG'!$F$8:$F$47,"Yes")} -> 0
B36: Total located interruptions | C36: {=SUM($C$26:$C$35)} -> 0
B38: Interruptions with no location recorded | C38: {=MAX(0,$C$11-$C$36)} -> 0
B40: Rates display as blank until at least one valid run is recorded. Counts are not conclusions: a clean five-run baseline is a legitimate result and does not establish that interruptions cannot occur, and a single interruption does not establish a pattern.

Sheet TEST ITERATIONS
A2: Test Iterations
A3: Planned and completed experiments following FQA-001 · One variable per iteration
A5: A new test earns its place only when a real observation prompts it. Change one variable, hold the rest constant, and state in advance what result would count as evidence against the hypothesis.
A7: Test ID | B7: Trigger / finding from previous test | C7: Question | D7: Hypothesis | E7: Variable changed | F7: Variables held constant | G7: Procedure change | H7: Result | I7: Conclusion | J7: Next test
A8: FQA-002
A9: FQA-003
A10: FQA-004
A11: FQA-005
A12: FQA-006
A13: FQA-007
A14: FQA-008
A15: FQA-009
A16: FQA-010
A24: Later phases may extend to iPhone cellular mobility, Apple Watch service continuity, degraded connectivity, recovery behaviour, ecosystem and device transitions, comparative reference devices, and controlled real-world scenarios. None of these belong in FQA-001.
